Workbook
Name ActualDataRange: MasterSheet!$B$2:$AL$129
Name DataColumnRange: MasterSheet!$A$2:$A$129
Name dataRowRange: MasterSheet!$B$1:$AL$1

Sheet Configuration
A1: Parameter | B1: Parameterkey | C1: ParameterValue
A2: LoginUsername | B2: username | C2: sumit.choudhary@delta.com
A3: LoginPassword | B3: Password | C3: Delta2
A4: Browser | B4: QA | C4: Chrome
A5: SIEnvWebsite | B5: url | C5: si.deltacargo.com

Sheet TestCaseConfig
A1: TestScenarios | B1: TestCaseExecution | C1: TestCasename | D1: QA SPOC | E1: TestCase Count
A2: createAndConfirmAdvanceBookingForGeneralCargo | B2: Yes | C2: ABGeneralCargo | D2: Sumit | E2: =COUNTA(ABGeneralCargo!A:A)-1 -> 6
A3: createAndConfirmAdvanceBookingForPerishables | B3: Yes | C3: ABPerishable | D3: Sumit | E3: =COUNTA(ABPerishable!A:A)-1 -> 10
A4: createAndConfirmAdvanceBookingForPharma | B4: Yes | C4: ABPharma | D4: Sumit | E4: =COUNTA(ABPharma!A:A)-1 -> 10
A5: createAndConfirmAdvanceBookingForMedical | B5: Yes | C5: ABMedical | D5: Sumit | E5: =COUNTA(ABMedical!A:A)-1 -> 12
A6: createAndConfirmAdvanceBookingForValuables | B6: Yes | C6: ABValuables | D6: Sumit | E6: =COUNTA(ABValuables!A:A)-1 -> 4
A7: createAndConfirmAdvanceBookingForHumanRemains | B7: Yes | C7: ABHumanRemains | D7: Sumit | E7: =COUNTA(ABHumanRemains!A:A)-1 -> 6
A8: createAndConfirmAdvanceBookingForLiveAnimals | B8: Yes | C8: ABLiveAnimal | D8: Sumit | E8: =COUNTA(ABLiveAnimal!A:A)-1 -> 14
A9: createAndConfirmGuidedBookingForParcelLessThan16Oz | B9: Yes | C9: GBParcel16Oz | D9: Bhavani | E9: =COUNTA(GBParcel16Oz!A:A)-1 -> 6
A10: createAndConfirmGuidedBookingParcels | B10: Yes | C10: GBParcel | D10: Bhavani | E10: =COUNTA(GBParcel!A:A)-1 -> 6
A11: createAndConfirmGuidedBookingPetsAndLive | B11: Yes | C11: GBPetLive | D11: Bhavani | E11: =COUNTA(GBPetLive!A:A)-1 -> 12
A12: createAndConfirmGuidedBookingPerishables | B12: Yes | C12: GBPerishable | D12: Bhavani | E12: =COUNTA(GBPerishable!A:A)-1 -> 10
A13: createAndConfirmGuidedBookingPharma | B13: Yes | C13: GBPharma | D13: Bhavani | E13: =COUNTA(GBPharma!A:A)-1 -> 10
A14: createAndConfirmGuidedBookingMedical | B14: Yes | C14: GBMedical | D14: Bhavani | E14: =COUNTA(GBMedical!A:A)-1 -> 12
A15: createAndConfirmGuidedBookingValuables | B15: Yes | C15: GBSpecialty | D15: Bhavani | E15: =COUNTA(GBSpecialty!A:A)-1 -> 4
A16: createAndConfirmGuidedBookingHumanRemains | B16: Yes | C16: GBHumanRemains | D16: Bhavani | E16: =COUNTA(GBHumanRemains!A:A)-1 -> 6

Sheet MasterSheet
A1: Testcase | B1: ShipmentContains | C1: ShipmentProduct | D1: LoginUsername | E1: LoginPassword | F1: SearchFlightFlag | G1: guidedBookingOption | H1: ShipmentOrigin | I1: ShipmentDestination | J1: TypeOfShipments | K1: ShipmentDescription | L1: ShipmentWeight | M1: ShipmentWeightUnits | N1: ShipmentQuantity | O1: ShipmentLength | P1: ShipmentWidth | Q1: ShipmentHeight | R1: ShipmentUnit | S1: ShipmentVolumeUnit | T1: ShipmentDoPiecesBeRotated | U1: ShipmentDoPiecesContainDangerousGoods | V1: ShipmentBePreScreened | W1: ShipmentCalendarDate | X1: ShipmentRequireDeltaContainer | Y1: ContainerType | Z1: RecipientInformationAccountNumber | AA1: ShipmentTemplateName | AB1: ShipmentPaymentMethod | AC1: PetAgeAndUnit | AD1: Address1 | AE1: Address2 | AF1: City | AG1: State | AH1: Postal | AI1: AccountNumber | AJ1: AccountType | AK1: AWB | AL1: ParcelQuantiy
A2: =_xlfn.CONCAT("createAndConfirmAdvanceBooking",SUBSTITUTE(B2," ","_"),"_",SUBSTITUTE(C2," ","_"),"_",SUBSTITUTE(SUBSTITUTE(SUBSTITUTE(SUBSTITUTE(SUBSTITUTE(SUBSTITUTE(SUBSTITUTE(J2," ",""),"-",""),"/",""),"–",""),"+",""),"°",""),",",""),"_",SUBSTITUTE(AJ2," ","_")) -> createAndConfirmAdvanceBookingGeneral_Cargo_STANDARD_Loose_Domestic | B2: General Cargo | C2: STANDARD | D2: sumit.choudhary@delta.com | E2: Delta2 | F2: TRUE | G2: NA | H2: ATL | I2: MSP | J2: Loose | K2: Test General Cargo | L2: 30 | M2: KG | N2: 1 | O2: 10 | P2: 10 | Q2: 10 | R2: IN | S2: Cubic Feet | T2: No | U2: No | V2: No | W2: 2 | X2: No | Y2: NA | Z2: 000260018 | AA2: GeneralCargoTemplate | AB2: CreditCard | AC2: NA | AD2: Test1 | AE2: Test2 | AF2: Atlanta | AG2: Georgia | AH2: 55055 | AI2: 000075010 | AJ2: Domestic
A3: =_xlfn.CONCAT("createAndConfirmAdvanceBooking",SUBSTITUTE(B3," ","_"),"_",SUBSTITUTE(C3," ","_"),"_",SUBSTITUTE(SUBSTITUTE(SUBSTITUTE(SUBSTITUTE(SUBSTITUTE(SUBSTITUTE(SUBSTITUTE(J3," ",""),"-",""),"/",""),"–",""),"+",""),"°",""),",",""),"_",SUBSTITUTE(AJ3," ","_")) -> createAndConfirmAdvanceBookingGeneral_Cargo_DSH_Loose_Domestic | B3: General Cargo | C3: DSH | D3: sumit.choudhary@delta.com | E3: Delta2 | F3: TRUE | G3: NA | H3: JFK | I3: ATL | J3: Loose | K3: Test General Cargo | L3: 90 | M3: KG | N3: 1 | O3: 10 | P3: 10 | Q3: 10 | R3: IN | S3: Cubic Feet | T3: No | U3: No | V3: No | W3: 2 | X3: No | Y3: NA | Z3: 000260018 | AA3: GeneralCargoTemplate | AB3: CreditCard | AC3: NA | AD3: Test1 | AE3: Test2 | AF3: Atlanta | AG3: Georgia | AH3: 55055 | AI3: 000075010 | AJ3: Domestic
A4: =_xlfn.CONCAT("createAndConfirmAdvanceBooking",SUBSTITUTE(B4," ","_"),"_",SUBSTITUTE(C4," ","_"),"_",SUBSTITUTE(SUBSTITUTE(SUBSTITUTE(SUBSTITUTE(SUBSTITUTE(SUBSTITUTE(SUBSTITUTE(J4," ",""),"-",""),"/",""),"–",""),"+",""),"°",""),",",""),"_",SUBSTITUTE(AJ4," ","_")) -> createAndConfirmAdvanceBookingGeneral_Cargo_DMD_Loose_Domestic | B4: General Cargo | C4: DMD | D4: sumit.choudhary@delta.com | E4: Delta2 | F4: TRUE | G4: NA | H4: JFK | I4: DTW | J4: Loose | K4: Test General Cargo | L4: 10 | M4: KG | N4: 1 | O4: 10 | P4: 10 | Q4: 10 | R4: IN | S4: Cubic Feet | T4: No | U4: No | V4: No | W4: 2 | X4: No | Y4: NA | Z4: 000260018 | AA4: GeneralCargoTemplate | AB4: CreditCard | AC4: NA | AD4: Test1 | AE4: Test2 | AF4: Atlanta | AG4: Georgia | AH4: 55055 | AI4: 000075010 | AJ4: Domestic
A5: =_xlfn.CONCAT("createAndConfirmAdvanceBooking",SUBSTITUTE(B5," ","_"),"_",SUBSTITUTE(C5," ","_"),"_",SUBSTITUTE(SUBSTITUTE(SUBSTITUTE(SUBSTITUTE(SUBSTITUTE(SUBSTITUTE(SUBSTITUTE(J5," ",""),"-",""),"/",""),"–",""),"+",""),"°",""),",",""),"_",SUBSTITUTE(AJ5," ","_")) -> createAndConfirmAdvanceBookingGeneral_Cargo_STANDARD_Loose_International | B5: General Cargo | C5: STANDARD | D5: sumit.choudhary@delta.com | E5: Delta2 | F5: TRUE | G5: NA | H5: ATL | I5: MSP | J5: Loose | K5: Test General Cargo | L5: 30 | M5: KG | N5: 1 | O5: 10 | P5: 10 | Q5: 10 | R5: IN | S5: Cubic Feet | T5: No | U5: No | V5: No | W5: 2 | X5: No | Y5: NA | Z5: 000260018 | AA5: GeneralCargoTemplate | AB5: CreditCard | AC5: NA | AD5: Test1 | AE5: Test2 | AF5: Atlanta | AG5: Georgia | AH5: 55055 | AI5: 171276181 | AJ5: International
A6: =_xlfn.CONCAT("createAndConfirmAdvanceBooking",SUBSTITUTE(B6," ","_"),"_",SUBSTITUTE(C6," ","_"),"_",SUBSTITUTE(SUBSTITUTE(SUBSTITUTE(SUBSTITUTE(SUBSTITUTE(SUBSTITUTE(SUBSTITUTE(J6," ",""),"-",""),"/",""),"–",""),"+",""),"°",""),",",""),"_",SUBSTITUTE(AJ6," ","_")) -> createAndConfirmAdvanceBookingGeneral_Cargo_DSH_Loose_International | B6: General Cargo | C6: DSH | D6: sumit.choudhary@delta.com | E6: Delta2 | F6: TRUE | G6: NA | H6: JFK | I6: ATL | J6: Loose | K6: Test General Cargo | L6: 90 | M6: KG | N6: 1 | O6: 10 | P6: 10 | Q6: 10 | R6: IN | S6: Cubic Feet | T6: No | U6: No | V6: No | W6: 2 | X6: No | Y6: NA | Z6: 000260018 | AA6: GeneralCargoTemplate | AB6: CreditCard | AC6: NA | AD6: Test1 | AE6: Test2 | AF6: Atlanta | AG6: Georgia | AH6: 55055 | AI6: 171276181 | AJ6: International
A7: =_xlfn.CONCAT("createAndConfirmAdvanceBooking",SUBSTITUTE(B7," ","_"),"_",SUBSTITUTE(C7," ","_"),"_",SUBSTITUTE(SUBSTITUTE(SUBSTITUTE(SUBSTITUTE(SUBSTITUTE(SUBSTITUTE(SUBSTITUTE(J7," ",""),"-",""),"/",""),"–",""),"+",""),"°",""),",",""),"_",SUBSTITUTE(AJ7," ","_")) -> createAndConfirmAdvanceBookingGeneral_Cargo_DMD_Loose_International | B7: General Cargo | C7: DMD | D7: sumit.choudhary@delta.com | E7: Delta2 | F7: TRUE | G7: NA | H7: JFK | I7: DTW | J7: Loose | K7: Test General Cargo | L7: 10 | M7: KG | N7: 1 | O7: 10 | P7: 10 | Q7: 10 | R7: IN | S7: Cubic Feet | T7: No | U7: No | V7: No | W7: 2 | X7: No | Y7: NA | Z7: 000260018 | AA7: GeneralCargoTemplate | AB7: CreditCard | AC7: NA | AD7: Test1 | AE7: Test2 | AF7: Atlanta | AG7: Georgia | AH7: 55055 | AI7: 171276181 | AJ7: International
A8: =_xlfn.CONCAT("createAndConfirmAdvanceBooking",SUBSTITUTE(B8," ","_"),"_",SUBSTITUTE(C8," ","_"),"_",SUBSTITUTE(SUBSTITUTE(SUBSTITUTE(SUBSTITUTE(SUBSTITUTE(SUBSTITUTE(SUBSTITUTE(J8," ",""),"-",""),"/",""),"–",""),"+",""),"°",""),",",""),"_",SUBSTITUTE(AJ8," ","_")) -> createAndConfirmAdvanceBookingPerishable_FRESH_Fresh1Activecontainer_Domestic | B8: Perishable | C8: FRESH | D8: sumit.choudhary@delta.com | E8: Delta2 | F8: TRUE | G8: NA | H8: ATL | I8: MSP | J8: Fresh 1 - Active container | K8: Test Perishables | L8: 10 | M8: LB | N8: 1 | O8: 10 | P8: 10 | Q8: 10 | R8: IN | S8: Cubic Feet | T8: No | U8: No | V8: No | W8: 2 | X8: No | Y8: NA | Z8: 000260018 | AA8: GeneralCargoTemplate | AB8: CreditCard | AC8: NA | AD8: Test1 | AE8: Test2 | AF8: Atlanta | AG8: Georgia | AH8: 55055 | AI8: 000075010 | AJ8: Domestic
A9: =_xlfn.CONCAT("createAndConfirmAdvanceBooking",SUBSTITUTE(B9," ","_"),"_",SUBSTITUTE(C9," ","_"),"_",SUBSTITUTE(SUBSTITUTE(SUBSTITUTE(SUBSTITUTE(SUBSTITUTE(SUBSTITUTE(SUBSTITUTE(J9," ",""),"-",""),"/",""),"–",""),"+",""),"°",""),",",""),"_",SUBSTITUTE(AJ9," ","_")) -> createAndConfirmAdvanceBookingPerishable_FRESH_Fresh2Temperaturecontrolledbetween2Cto8C_Domestic | B9: Perishable | C9: FRESH | D9: sumit.choudhary@delta.com | E9: Delta2 | F9: TRUE | G9: NA | H9: JFK | I9: ATL | J9: Fresh 2 - Temperature controlled between +2°C to 8°C | K9: Test Perishables | L9: 10 | M9: LB | N9: 1 | O9: 10 | P9: 10 | Q9: 10 | R9: IN | S9: Cubic Feet | T9: No | U9: No | V9: No | W9: 2 | X9: No | Y9: NA | Z9: 000260018 | AA9: GeneralCargoTemplate | AB9: CreditCard | AC9: NA | AD9: Test1 | AE9: Test2 | AF9: Atlanta | AG9: Georgia | AH9: 55055 | AI9: 000075010 | AJ9: Domestic
A10: =_xlfn.CONCAT("createAndConfirmAdvanceBooking",SUBSTITUTE(B10," ","_"),"_",SUBSTITUTE(C10," ","_"),"_",SUBSTITUTE(SUBSTITUTE(SUBSTITUTE(SUBSTITUTE(SUBSTITUTE(SUBSTITUTE(SUBSTITUTE(J10," ",""),"-",""),"/",""),"–",""),"+",""),"°",""),",",""),"_",SUBSTITUTE(AJ10," ","_")) -> createAndConfirmAdvanceBookingPerishable_DASH_Fresh3Flowersbetween2Cto25C_Domestic | B10: Perishable | C10: DASH | D10: sumit.choudhary@delta.com | E10: Delta2 | F10: TRUE | G10: NA | H10: JFK | I10: DTW | J10: Fresh 3 - Flowers between +2°C to 25°C | K10: Test Perishables | L10: 10 | M10: LB | N10: 1 | O10: 10 | P10: 10 | Q10: 10 | R10: IN | S10: Cubic Feet | T10: No | U10: No | V10: No | W10: 2 | X10: No | Y10: NA | Z10: 000260018 | AA10: GeneralCargoTemplate | AB10: CreditCard | AC10: NA | AD10: Test1 | AE10: Test2 | AF10: Atlanta | AG10: Georgia | AH10: 55055 | AI10: 000075010 | AJ10: Domestic
A11: =_xlfn.CONCAT("createAndConfirmAdvanceBooking",SUBSTITUTE(B11," ","_"),"_",SUBSTITUTE(C11," ","_"),"_",SUBSTITUTE(SUBSTITUTE(SUBSTITUTE(SUBSTITUTE(SUBSTITUTE(SUBSTITUTE(SUBSTITUTE(J11," ",""),"-",""),"/",""),"–",""),"+",""),"°",""),",",""),"_",SUBSTITUTE(AJ11," ","_")) -> createAndConfirmAdvanceBookingPerishable_DHV_Fresh3Foodstuffsbetween2Cto25C_Domestic | B11: Perishable | C11: DHV | D11: sumit.choudhary@delta.com | E11: Delta2 | F11: TRUE | G11: NA | H11: ATL | I11: MSP | J11: Fresh 3 - Foodstuffs between +2°C to 25°C | K11: Test Perishables | L11: 10 | M11: LB | N11: 1 | O11: 10 | P11: 10 | Q11: 10 | R11: IN | S11: Cubic Feet | T11: No | U11: No | V11: No | W11: 2 | X11: No | Y11: NA | Z11: 000260018 | AA11: GeneralCargoTemplate | AB11: CreditCard | AC11: NA | AD11: Test1 | AE11: Test2 | AF11: Atlanta | AG11: Georgia | AH11: 55055 | AI11: 000075010 | AJ11: Domestic
A12: =_xlfn.CONCAT("createAndConfirmAdvanceBooking",SUBSTITUTE(B12," ","_"),"_",SUBSTITUTE(C12," ","_"),"_",SUBSTITUTE(SUBSTITUTE(SUBSTITUTE(SUBSTITUTE(SUBSTITUTE(SUBSTITUTE(SUBSTITUTE(J12," ",""),"-",""),"/",""),"–",""),"+",""),"°",""),",",""),"_",SUBSTITUTE(AJ12," ","_")) -> createAndConfirmAdvanceBookingPerishable_DMD_Fresh3Seafoodbetween2Cto25C_Domestic | B12: Perishable | C12: DMD | D12: sumit.choudhary@delta.com | E12: Delta2 | F12: TRUE | G12: NA | H12: JFK | I12: ATL | J12: Fresh 3 - Seafood between +2°C to 25°C | K12: Test Perishables | L12: 10 | M12: LB | N12: 1 | O12: 10 | P12: 10 | Q12: 10 | R12: IN | S12: Cubic Feet | T12: No | U12: No | V12: No | W12: 2 | X12: No | Y12: NA | Z12: 000260018 | AA12: GeneralCargoTemplate | AB12: CreditCard | AC12: NA | AD12: Test1 | AE12: Test2 | AF12: Atlanta | AG12: Georgia | AH12: 55055 | AI12: 000075010 | AJ12: Domestic
A13: =_xlfn.CONCAT("createAndConfirmAdvanceBooking",SUBSTITUTE(B13," ","_"),"_",SUBSTITUTE(C13," ","_"),"_",SUBSTITUTE(SUBSTITUTE(SUBSTITUTE(SUBSTITUTE(SUBSTITUTE(SUBSTITUTE(SUBSTITUTE(J13," ",""),"-",""),"/",""),"–",""),"+",""),"°",""),",",""),"_",SUBSTITUTE(AJ13," ","_")) -> createAndConfirmAdvanceBookingPerishable_FRESH_Fresh1Activecontainer_International | B13: Perishable | C13: FRESH | D13: sumit.choudhary@delta.com | E13: Delta2 | F13: TRUE | G13: NA | H13: ATL | I13: MSP | J13: Fresh 1 - Active container | K13: Test Perishables | L13: 10 | M13: LB | N13: 1 | O13: 10 | P13: 10 | Q13: 10 | R13: IN | S13: Cubic Feet | T13: No | U13: No | V13: No | W13: 2 | X13: No | Y13: NA | Z13: 000260018 | AA13: GeneralCargoTemplate | AB13: CreditCard | AC13: NA | AD13: Test1 | AE13: Test2 | AF13: Atlanta | AG13: Georgia | AH13: 55055 | AI13: 171276181 | AJ13: International
... A63: =_xlfn.CONCAT("createAndConfirmAdvanceBooking",SUBSTITUTE(B63," ","_"),"_",SUBSTITUTE(C63," ","_"),"_",SUBSTITUTE(SUBSTITUTE(SUBSTITUTE(SUBSTITUTE(SUBSTITUTE(SUBSTITUTE(SUBSTITUTE(J63," ",""),"-",""),"/",""),"–",""),"+",""),"°",""),",",""),"_",SUBSTITUTE(AJ63," ","_")) -> createAndConfirmAdvanceBookingLiveAnimals_LIVE_HatchingEggs_International | B63: LiveAnimals | C63: LIVE | D63: sumit.choudhary@delta.com | E63: Delta2 | F63: TRUE | G63: NA | H63: JFK | I63: ATL | J63: Hatching Eggs | K63: Test Pet and Live | L63: 10 | M63: LB | N63: 1 | O63: 10 | P63: 10 | Q63: 10 | R63: IN | S63: Cubic Feet | T63: No | U63: No | V63: No | W63: 2 | X63: No | Y63: NA | Z63: 000260018 | AA63: GeneralCargoTemplate | AB63: CreditCard | AC63: NA | AD63: Test1 | AE63: Test2 | AF63: Atlanta | AG63: Georgia | AH63: 55055 | AI63: 171276181 | AJ63: International
A64: =_xlfn.CONCAT("createAndConfirmGuidedBooking",SUBSTITUTE(B64," ","_"),"_",SUBSTITUTE(C64," ","_"),"_",SUBSTITUTE(SUBSTITUTE(SUBSTITUTE(SUBSTITUTE(SUBSTITUTE(SUBSTITUTE(SUBSTITUTE(J64," ",""),"-",""),"/",""),"–",""),"+",""),"°",""),",",""),"_",SUBSTITUTE(AJ64," ","_")) -> createAndConfirmGuidedBookingParcellessthan16OZ_STANDARD_NA_Domestic | B64: Parcellessthan16OZ | C64: STANDARD | D64: sumit.choudhary@delta.com | E64: Delta2 | F64: TRUE | G64: NA | H64: ATL | I64: MSP | J64: NA | K64: Test Parcel less | L64: 10 | M64: OZ | N64: 1 | O64: 10 | P64: 10 | Q64: 10 | R64: CM | S64: Cubic Feet | T64: No | U64: No | V64: No | W64: 2 | X64: No | Y64: NA | Z64: 000260018 | AA64: GeneralCargoTemplate | AB64: CreditCard | AC64: NA | AD64: Test1 | AE64: Test2 | AF64: Atlanta | AG64: Georgia | AH64: 55055 | AI64: 000075010 | AJ64: Domestic
A65: =_xlfn.CONCAT("createAndConfirmGuidedBooking",SUBSTITUTE(B65," ","_"),"_",SUBSTITUTE(C65," ","_"),"_",SUBSTITUTE(SUBSTITUTE(SUBSTITUTE(SUBSTITUTE(SUBSTITUTE(SUBSTITUTE(SUBSTITUTE(J65," ",""),"-",""),"/",""),"–",""),"+",""),"°",""),",",""),"_",SUBSTITUTE(AJ65," ","_")) -> createAndConfirmGuidedBookingParcellessthan16OZ_DSH_NA_Domestic | B65: Parcellessthan16OZ | C65: DSH | D65: sumit.choudhary@delta.com | E65: Delta2 | F65: TRUE | G65: NA | H65: ATL | I65: MSP | J65: NA | K65: Test Parcel less | L65: 20 | M65: OZ | N65: 2 | O65: 10 | P65: 10 | Q65: 10 | R65: IN | S65: Cubic Feet | T65: Yes | U65: No | V65: Yes | W65: 2 | X65: No | Y65: NA | Z65: 000260018 | AA65: GeneralCargoTemplate | AB65: CreditCard | AC65: NA | AD65: Test1 | AE65: Test2 | AF65: Atlanta | AG65: Georgia | AH65: 55055 | AI65: 000075010 | AJ65: Domestic
A66: =_xlfn.CONCAT("createAndConfirmGuidedBooking",SUBSTITUTE(B66," ","_"),"_",SUBSTITUTE(C66," ","_"),"_",SUBSTITUTE(SUBSTITUTE(SUBSTITUTE(SUBSTITUTE(SUBSTITUTE(SUBSTITUTE(SUBSTITUTE(J66," ",""),"-",""),"/",""),"–",""),"+",""),"°",""),",",""),"_",SUBSTITUTE(AJ66," ","_")) -> createAndConfirmGuidedBookingParcellessthan16OZ_DMD_NA_Domestic | B66: Parcellessthan16OZ | C66: DMD | D66: sumit.choudhary@delta.com | E66: Delta2 | F66: TRUE | G66: NA | H66: ATL | I66: JFK | J66: NA | K66: Test Parcel less | L66: 40 | M66: OZ | N66: 4 | O66: 10 | P66: 10 | Q66: 10 | R66: CM | S66: Cubic Feet | T66: No | U66: No | V66: No | W66: 2 | X66: No | Y66: NA | Z66: 000260018 | AA66: GeneralCargoTemplate | AB66: CreditCard | AC66: NA | AD66: Test1 | AE66: Test2 | AF66: Atlanta | AG66: Georgia | AH66: 55055 | AI66: 000075010 | AJ66: Domestic
A67: =_xlfn.CONCAT("createAndConfirmGuidedBooking",SUBSTITUTE(B67," ","_"),"_",SUBSTITUTE(C67," ","_"),"_",SUBSTITUTE(SUBSTITUTE(SUBSTITUTE(SUBSTITUTE(SUBSTITUTE(SUBSTITUTE(SUBSTITUTE(J67," ",""),"-",""),"/",""),"–",""),"+",""),"°",""),",",""),"_",SUBSTITUTE(AJ67," ","_")) -> createAndConfirmGuidedBookingParcellessthan16OZ_GENERAL_NA_International | B67: Parcellessthan16OZ | C67: GENERAL | D67: sumit.choudhary@delta.com | E67: Delta2 | F67: TRUE | G67: NA | H67: ATL | I67: MSP | J67: NA | K67: Test Parcel less | L67: 10 | M67: OZ | N67: 1 | O67: 10 | P67: 10 | Q67: 10 | R67: IN | S67: Cubic Feet | T67: Yes | U67: No | V67: Yes | W67: 2 | X67: No | Y67: NA | Z67: 000260018 | AA67: GeneralCargoTemplate | AB67: CreditCard | AC67: NA | AD67: Test1 | AE67: Test2 | AF67: Atlanta | AG67: Georgia | AH67: 55055 | AI67: 171276181 | AJ67: International
A68: =_xlfn.CONCAT("createAndConfirmGuidedBooking",SUBSTITUTE(B68," ","_"),"_",SUBSTITUTE(C68," ","_"),"_",SUBSTITUTE(SUBSTITUTE(SUBSTITUTE(SUBSTITUTE(SUBSTITUTE(SUBSTITUTE(SUBSTITUTE(J68," ",""),"-",""),"/",""),"–",""),"+",""),"°",""),",",""),"_",SUBSTITUTE(AJ68," ","_")) -> createAndConfirmGuidedBookingParcellessthan16OZ_EXPRESS_NA_International | B68: Parcellessthan16OZ | C68: EXPRESS | D68: sumit.choudhary@delta.com | E68: Delta2 | F68: TRUE | G68: NA | H68: ATL | I68: LHR | J68: NA | K68: Test Parcel less | L68: 40 | M68: OZ | N68: 3 | O68: 10 | P68: 10 | Q68: 10 | R68: CM | S68: Cubic Feet | T68: No | U68: No | V68: No | W68: 2 | X68: No | Y68: NA | Z68: 000260018 | AA68: GeneralCargoTemplate | AB68: CreditCard | AC68: NA | AD68: Test1 | AE68: Test2 | AF68: Atlanta | AG68: Georgia | AH68: 55055 | AI68: 171276181 | AJ68: International
A69: =_xlfn.CONCAT("createAndConfirmGuidedBooking",SUBSTITUTE(B69," ","_"),"_",SUBSTITUTE(C69," ","_"),"_",SUBSTITUTE(SUBSTITUTE(SUBSTITUTE(SUBSTITUTE(SUBSTITUTE(SUBSTITUTE(SUBSTITUTE(J69," ",""),"-",""),"/",""),"–",""),"+",""),"°",""),",",""),"_",SUBSTITUTE(AJ69," ","_")) -> createAndConfirmGuidedBookingParcellessthan16OZ_CRITICAL_NA_International | B69: Parcellessthan16OZ | C69: CRITICAL | D69: sumit.choudhary@delta.com | E69: Delta2 | F69: TRUE | G69: NA | H69: ATL | I69: LHR | J69: NA | K69: Test Parcel less | L69: 90 | M69: OZ | N69: 4 | O69: 10 | P69: 10 | Q69: 10 | R69: IN | S69: Cubic Feet | T69: Yes | U69: No | V69: Yes | W69: 2 | X69: No | Y69: NA | Z69: 000260018 | AA69: GeneralCargoTemplate | AB69: CreditCard | AC69: NA | AD69: Test1 | AE69: Test2 | AF69: Atlanta | AG69: Georgia | AH69: 55055 | AI69: 171276181 | AJ69: International
A70: =_xlfn.CONCAT("createAndConfirmGuidedBooking",SUBSTITUTE(B70," ","_"),"_",SUBSTITUTE(C70," ","_"),"_",SUBSTITUTE(SUBSTITUTE(SUBSTITUTE(SUBSTITUTE(SUBSTITUTE(SUBSTITUTE(SUBSTITUTE(J70," ",""),"-",""),"/",""),"–",""),"+",""),"°",""),",",""),"_",SUBSTITUTE(AJ70," ","_")) -> createAndConfirmGuidedBookingParcels_STANDARD_NA_Domestic | B70: Parcels | C70: STANDARD | D70: sumit.choudhary@delta.com | E70: Delta2 | F70: TRUE | G70: NA | H70: ATL | I70: MSP | J70: NA | K70: Test Parcels | L70: 30 | M70: KG | N70: 1 | O70: 10 | P70: 10 | Q70: 10 | R70: CM | S70: NA | T70: Yes | U70: No | V70: No | W70: 2 | X70: No | Y70: NA | Z70: 000260018 | AA70: GeneralCargoTemplate | AB70: CreditCard | AC70: NA | AD70: Test1 | AE70: Test2 | AF70: Atlanta | AG70: Georgia | AH70: 55055 | AI70: 000075010 | AJ70: Domestic | AL70: 2
A71: =_xlfn.CONCAT("createAndConfirmGuidedBooking",SUBSTITUTE(B71," ","_"),"_",SUBSTITUTE(C71," ","_"),"_",SUBSTITUTE(SUBSTITUTE(SUBSTITUTE(SUBSTITUTE(SUBSTITUTE(SUBSTITUTE(SUBSTITUTE(J71," ",""),"-",""),"/",""),"–",""),"+",""),"°",""),",",""),"_",SUBSTITUTE(AJ71," ","_")) -> createAndConfirmGuidedBookingParcels_DSH_NA_Domestic | B71: Parcels | C71: DSH | D71: sumit.choudhary@delta.com | E71: Delta2 | F71: TRUE | G71: NA | H71: ORD | I71: SEA | J71: NA | K71: Test Parcels | L71: 60 | M71: LB | N71: 3 | O71: 10 | P71: 10 | Q71: 10 | R71: IN | S71: NA | T71: No | U71: No | V71: Yes | W71: 2 | X71: No | Y71: NA | Z71: 000260018 | AA71: GeneralCargoTemplate | AB71: CreditCard | AC71: NA | AD71: Test1 | AE71: Test2 | AF71: Atlanta | AG71: Georgia | AH71: 55055 | AI71: 000075010 | AJ71: Domestic | AL71: 3
A72: =_xlfn.CONCAT("createAndConfirmGuidedBooking",SUBSTITUTE(B72," ","_"),"_",SUBSTITUTE(C72," ","_"),"_",SUBSTITUTE(SUBSTITUTE(SUBSTITUTE(SUBSTITUTE(SUBSTITUTE(SUBSTITUTE(SUBSTITUTE(J72," ",""),"-",""),"/",""),"–",""),"+",""),"°",""),",",""),"_",SUBSTITUTE(AJ72," ","_")) -> createAndConfirmGuidedBookingParcels_DMD_NA_Domestic | B72: Parcels | C72: DMD | D72: sumit.choudhary@delta.com | E72: Delta2 | F72: TRUE | G72: NA | H72: JFK | I72: MSP | J72: NA | K72: Test Parcels | L72: 90 | M72: KG | N72: 4 | O72: 10 | P72: 10 | Q72: 10 | R72: CM | S72: NA | T72: Yes | U72: No | V72: No | W72: 2 | X72: No | Y72: NA | Z72: 000260018 | AA72: GeneralCargoTemplate | AB72: CreditCard | AC72: NA | AD72: Test1 | AE72: Test2 | AF72: Atlanta | AG72: Georgia | AH72: 55055 | AI72: 000075010 | AJ72: Domestic | AL72: 4
A73: =_xlfn.CONCAT("createAndConfirmGuidedBooking",SUBSTITUTE(B73," ","_"),"_",SUBSTITUTE(C73," ","_"),"_",SUBSTITUTE(SUBSTITUTE(SUBSTITUTE(SUBSTITUTE(SUBSTITUTE(SUBSTITUTE(SUBSTITUTE(J73," ",""),"-",""),"/",""),"–",""),"+",""),"°",""),",",""),"_",SUBSTITUTE(AJ73," ","_")) -> createAndConfirmGuidedBookingParcels_GENERAL_NA_International | B73: Parcels | C73: GENERAL | D73: sumit.choudhary@delta.com | E73: Delta2 | F73: TRUE | G73: NA | H73: ATL | I73: LHR | J73: NA | K73: Test Parcels | L73: 30 | M73: LB | N73: 1 | O73: 10 | P73: 10 | Q73: 10 | R73: IN | S73: NA | T73: No | U73: No | V73: Yes | W73: 2 | X73: No | Y73: NA | Z73: 000260018 | AA73: GeneralCargoTemplate | AB73: CreditCard | AC73: NA | AD73: Test1 | AE73: Test2 | AF73: Atlanta | AG73: Georgia | AH73: 55055 | AI73: 171276181 | AJ73: International | AL73: 5
A74: =_xlfn.CONCAT("createAndConfirmGuidedBooking",SUBSTITUTE(B74," ","_"),"_",SUBSTITUTE(C74," ","_"),"_",SUBSTITUTE(SUBSTITUTE(SUBSTITUTE(SUBSTITUTE(SUBSTITUTE(SUBSTITUTE(SUBSTITUTE(J74," ",""),"-",""),"/",""),"–",""),"+",""),"°",""),",",""),"_",SUBSTITUTE(AJ74," ","_")) -> createAndConfirmGuidedBookingParcels_EXPRESS_HEAVY_NA_International | B74: Parcels | C74: EXPRESS HEAVY | D74: sumit.choudhary@delta.com | E74: Delta2 | F74: TRUE | G74: NA | H74: ATL | I74: LHR | J74: NA | K74: Test Parcels | L74: 60 | M74: KG | N74: 1 | O74: 10 | P74: 10 | Q74: 10 | R74: CM | S74: NA | T74: Yes | U74: No | V74: No | W74: 2 | X74: No | Y74: NA | Z74: 000260018 | AA74: GeneralCargoTemplate | AB74: CreditCard | AC74: NA | AD74: Test1 | AE74: Test2 | AF74: Atlanta | AG74: Georgia | AH74: 55055 | AI74: 171276181 | AJ74: International | AL74: 6
A75: =_xlfn.CONCAT("createAndConfirmGuidedBooking",SUBSTITUTE(B75," ","_"),"_",SUBSTITUTE(C75," ","_"),"_",SUBSTITUTE(SUBSTITUTE(SUBSTITUTE(SUBSTITUTE(SUBSTITUTE(SUBSTITUTE(SUBSTITUTE(J75," ",""),"-",""),"/",""),"–",""),"+",""),"°",""),",",""),"_",SUBSTITUTE(AJ75," ","_")) -> createAndConfirmGuidedBookingParcels_CRITICAL_HEAVY_NA_International | B75: Parcels | C75: CRITICAL HEAVY | D75: sumit.choudhary@delta.com | E75: Delta2 | F75: TRUE | G75: NA | H75: ATL | I75: LHR | J75: NA | K75: Test Parcels | L75: 100 | M75: LB | N75: 1 | O75: 10 | P75: 10 | Q75: 10 | R75: IN | S75: NA | T75: No | U75: No | V75: Yes | W75: 2 | X75: No | Y75: NA | Z75: 000260018 | AA75: GeneralCargoTemplate | AB75: CreditCard | AC75: NA | AD75: Test1 | AE75: Test2 | AF75: Atlanta | AG75: Georgia | AH75: 55055 | AI75: 171276181 | AJ75: International | AL75: 7
A76: =_xlfn.CONCAT("createAndConfirmGuidedBooking",SUBSTITUTE(B76," ","_"),"_",SUBSTITUTE(C76," ","_"),"_",SUBSTITUTE(SUBSTITUTE(SUBSTITUTE(SUBSTITUTE(SUBSTITUTE(SUBSTITUTE(SUBSTITUTE(J76," ",""),"-",""),"/",""),"–",""),"+",""),"°",""),",",""),"_",SUBSTITUTE(AJ76," ","_")) -> createAndConfirmGuidedBookingPetsandLive_LIVE_Bird_Domestic | B76: PetsandLive | C76: LIVE | D76: sumit.choudhary@delta.com | E76: Delta2 | F76: TRUE | G76: NA | H76: ATL | I76: MSP | J76: Bird | K76: Test Pet and Live | L76: 10 | M76: KG | N76: 1 | O76: 10 | P76: 10 | Q76: 10 | R76: CM | S76: Cubic Feet | T76: No | U76: No | V76: No | W76: 2 | X76: No | Y76: NA | Z76: 000260018 | AA76: GeneralCargoTemplate | AB76: CreditCard | AC76: NA | AD76: Test1 | AE76: Test2 | AF76: Atlanta | AG76: Georgia | AH76: 55055 | AI76: 000075010 | AJ76: Domestic
A77: =_xlfn.CONCAT("createAndConfirmGuidedBooking",SUBSTITUTE(B77," ","_"),"_",SUBSTITUTE(C77," ","_"),"_",SUBSTITUTE(SUBSTITUTE(SUBSTITUTE(SUBSTITUTE(SUBSTITUTE(SUBSTITUTE(SUBSTITUTE(J77," ",""),"-",""),"/",""),"–",""),"+",""),"°",""),",",""),"_",SUBSTITUTE(AJ77," ","_")) -> createAndConfirmGuidedBookingPetsandLive_LIVE_Cat_Domestic | B77: PetsandLive | C77: LIVE | D77: sumit.choudhary@delta.com | E77: Delta2 | F77: TRUE | G77: NA | H77: ATL | I77: MSP | J77: Cat | K77: Test Pet and Live | L77: 20 | M77: LB | N77: 1 | O77: 10 | P77: 10 | Q77: 10 | R77: IN | S77: Cubic Feet | T77: Yes | U77: No | V77: Yes | W77: 3 | X77: No | Y77: NA | Z77: 000260018 | AA77: GeneralCargoTemplate | AB77: CreditCard | AC77: NA | AD77: Test1 | AE77: Test2 | AF77: Atlanta | AG77: Georgia | AH77: 55055 | AI77: 000075010 | AJ77: Domestic
A78: =_xlfn.CONCAT("createAndConfirmGuidedBooking",SUBSTITUTE(B78," ","_"),"_",SUBSTITUTE(C78," ","_"),"_",SUBSTITUTE(SUBSTITUTE(SUBSTITUTE(SUBSTITUTE(SUBSTITUTE(SUBSTITUTE(SUBSTITUTE(J78," ",""),"-",""),"/",""),"–",""),"+",""),"°",""),",",""),"_",SUBSTITUTE(AJ78," ","_")) -> createAndConfirmGuidedBookingPetsandLive_LIVE_ColdBloodedAnimal_Domestic | B78: PetsandLive | C78: LIVE | D78: sumit.choudhary@delta.com | E78: Delta2 | F78: TRUE | G78: NA | H78: ATL | I78: MSP | J78: Cold Blooded Animal | K78: Test Pet and Live | L78: 30 | M78: KG | N78: 1 | O78: 10 | P78: 10 | Q78: 10 | R78: CM | S78: Cubic Feet | T78: No | U78: No | V78: No | W78: 4 | X78: No | Y78: NA | Z78: 000260018 | AA78: GeneralCargoTemplate | AB78: CreditCard | AC78: NA | AD78: Test1 | AE78: Test2 | AF78: Atlanta | AG78: Georgia | AH78: 55055 | AI78: 000075010 | AJ78: Domestic
A79: =_xlfn.CONCAT("createAndConfirmGuidedBooking",SUBSTITUTE(B79," ","_"),"_",SUBSTITUTE(C79," ","_"),"_",SUBSTITUTE(SUBSTITUTE(SUBSTITUTE(SUBSTITUTE(SUBSTITUTE(SUBSTITUTE(SUBSTITUTE(J79," ",""),"-",""),"/",""),"–",""),"+",""),"°",""),",",""),"_",SUBSTITUTE(AJ79," ","_")) -> createAndConfirmGuidedBookingPetsandLive_LIVE_Dog_Domestic | B79: PetsandLive | C79: LIVE | D79: sumit.choudhary@delta.com | E79: Delta2 | F79: TRUE | G79: NA | H79: ATL | I79: MSP | J79: Dog | K79: Test Pet and Live | L79: 40 | M79: LB | N79: 1 | O79: 10 | P79: 10 | Q79: 10 | R79: IN | S79: Cubic Feet | T79: Yes | U79: No | V79: Yes | W79: 5 | X79: No | Y79: NA | Z79: 000260018 | AA79: GeneralCargoTemplate | AB79: CreditCard | AC79: NA | AD79: Test1 | AE79: Test2 | AF79: Atlanta | AG79: Georgia | AH79: 55055 | AI79: 000075010 | AJ79: Domestic
A80: =_xlfn.CONCAT("createAndConfirmGuidedBooking",SUBSTITUTE(B80," ","_"),"_",SUBSTITUTE(C80," ","_"),"_",SUBSTITUTE(SUBSTITUTE(SUBSTITUTE(SUBSTITUTE(SUBSTITUTE(SUBSTITUTE(SUBSTITUTE(J80," ",""),"-",""),"/",""),"–",""),"+",""),"°",""),",",""),"_",SUBSTITUTE(AJ80," ","_")) -> createAndConfirmGuidedBookingPetsandLive_LIVE_HatchingEggs_Domestic | B80: PetsandLive | C80: LIVE | D80: sumit.choudhary@delta.com | E80: Delta2 | F80: TRUE | G80: NA | H80: ATL | I80: MSP | J80: Hatching Eggs | K80: Test Pet and Live | L80: 10 | M80: KG | N80: 1 | O80: 10 | P80: 10 | Q80: 10 | R80: CM | S80: Cubic Feet | T80: No | U80: No | V80: No | W80: 6 | X80: No | Y80: NA | Z80: 000260018 | AA80: GeneralCargoTemplate | AB80: CreditCard | AC80: NA | AD80: Test1 | AE80: Test2 | AF80: Atlanta | AG80: Georgia | AH80: 55055 | AI80: 000075010 | AJ80: Domestic
A81: =_xlfn.CONCAT("createAndConfirmGuidedBooking",SUBSTITUTE(B81," ","_"),"_",SUBSTITUTE(C81," ","_"),"_",SUBSTITUTE(SUBSTITUTE(SUBSTITUTE(SUBSTITUTE(SUBSTITUTE(SUBSTITUTE(SUBSTITUTE(J81," ",""),"-",""),"/",""),"–",""),"+",""),"°",""),",",""),"_",SUBSTITUTE(AJ81," ","_")) -> createAndConfirmGuidedBookingPetsandLive_LIVE_WarmBloodedAnimal_Domestic | B81: PetsandLive | C81: LIVE | D81: sumit.choudhary@delta.com | E81: Delta2 | F81: TRUE | G81: NA | H81: ATL | I81: BWI | J81: Warm Blooded Animal | K81: Test Pet and Live | L81: 40 | M81: LB | N81: 1 | O81: 10 | P81: 10 | Q81: 10 | R81: IN | S81: Cubic Feet | T81: Yes | U81: No | V81: Yes | W81: 7 | X81: No | Y81: NA | Z81: 000260018 | AA81: GeneralCargoTemplate | AB81: CreditCard | AC81: NA | AD81: Test1 | AE81: Test2 | AF81: Atlanta | AG81: Georgia | AH81: 55055 | AI81: 000075010 | AJ81: Domestic
A82: =_xlfn.CONCAT("createAndConfirmGuidedBooking",SUBSTITUTE(B82," ","_"),"_",SUBSTITUTE(C82," ","_"),"_",SUBSTITUTE(SUBSTITUTE(SUBSTITUTE(SUBSTITUTE(SUBSTITUTE(SUBSTITUTE(SUBSTITUTE(J82," ",""),"-",""),"/",""),"–",""),"+",""),"°",""),",",""),"_",SUBSTITUTE(AJ82," ","_")) -> createAndConfirmGuidedBookingPetsandLive_SPECIALIZED_LIVE_Bird_International | B82: PetsandLive | C82: SPECIALIZED LIVE | D82: sumit.choudhary@delta.com | E82: Delta2 | F82: TRUE | G82: NA | H82: ATL | I82: MSP | J82: Bird | K82: Test Pet and Live | L82: 10 | M82: KG | N82: 1 | O82: 10 | P82: 10 | Q82: 10 | R82: CM | S82: Cubic Feet | T82: No | U82: No | V82: No | W82: 2 | X82: No | Y82: NA | Z82: 000260018 | AA82: GeneralCargoTemplate | AB82: CreditCard | AC82: NA | AD82: Test1 | AE82: Test2 | AF82: Atlanta | AG82: Georgia | AH82: 55055 | AI82: 171276181 | AJ82: International
A83: =_xlfn.CONCAT("createAndConfirmGuidedBooking",SUBSTITUTE(B83," ","_"),"_",SUBSTITUTE(C83," ","_"),"_",SUBSTITUTE(SUBSTITUTE(SUBSTITUTE(SUBSTITUTE(SUBSTITUTE(SUBSTITUTE(SUBSTITUTE(J83," ",""),"-",""),"/",""),"–",""),"+",""),"°",""),",",""),"_",SUBSTITUTE(AJ83," ","_")) -> createAndConfirmGuidedBookingPetsandLive_SPECIALIZED_LIVE_Cat_International | B83: PetsandLive | C83: SPECIALIZED LIVE | D83: sumit.choudhary@delta.com | E83: Delta2 | F83: TRUE | G83: NA | H83: ATL | I83: MSP | J83: Cat | K83: Test Pet and Live | L83: 30 | M83: LB | N83: 1 | O83: 10 | P83: 10 | Q83: 10 | R83: IN | S83: Cubic Feet | T83: Yes | U83: No | V83: Yes | W83: 3 | X83: No | Y83: NA | Z83: 000260018 | AA83: GeneralCargoTemplate | AB83: CreditCard | AC83: NA | AD83: Test1 | AE83: Test2 | AF83: Atlanta | AG83: Georgia | AH83: 55055 | AI83: 171276181 | AJ83: International
A84: =_xlfn.CONCAT("createAndConfirmGuidedBooking",SUBSTITUTE(B84," ","_"),"_",SUBSTITUTE(C84," ","_"),"_",SUBSTITUTE(SUBSTITUTE(SUBSTITUTE(SUBSTITUTE(SUBSTITUTE(SUBSTITUTE(SUBSTITUTE(J84," ",""),"-",""),"/",""),"–",""),"+",""),"°",""),",",""),"_",SUBSTITUTE(AJ84," ","_")) -> createAndConfirmGuidedBookingPetsandLive_SPECIALIZED_LIVE_ColdBloodedAnimal_International | B84: PetsandLive | C84: SPECIALIZED LIVE | D84: sumit.choudhary@delta.com | E84: Delta2 | F84: TRUE | G84: NA | H84: ATL | I84: MSP | J84: Cold Blooded Animal | K84: Test Pet and Live | L84: 60 | M84: KG | N84: 1 | O84: 10 | P84: 10 | Q84: 10 | R84: CM | S84: Cubic Feet | T84: No | U84: No | V84: No | W84: 4 | X84: No | Y84: NA | Z84: 000260018 | AA84: GeneralCargoTemplate | AB84: CreditCard | AC84: NA | AD84: Test1 | AE84: Test2 | AF84: Atlanta | AG84: Georgia | AH84: 55055 | AI84: 171276181 | AJ84: International
A85: =_xlfn.CONCAT("createAndConfirmGuidedBooking",SUBSTITUTE(B85," ","_"),"_",SUBSTITUTE(C85," ","_"),"_",SUBSTITUTE(SUBSTITUTE(SUBSTITUTE(SUBSTITUTE(SUBSTITUTE(SUBSTITUTE(SUBSTITUTE(J85," ",""),"-",""),"/",""),"–",""),"+",""),"°",""),",",""),"_",SUBSTITUTE(AJ85," ","_")) -> createAndConfirmGuidedBookingPetsandLive_SPECIALIZED_LIVE_Dog_International | B85: PetsandLive | C85: SPECIALIZED LIVE | D85: sumit.choudhary@delta.com | E85: Delta2 | F85: TRUE | G85: NA | H85: ATL | I85: MSP | J85: Dog | K85: Test Pet and Live | L85: 20 | M85: LB | N85: 1 | O85: 10 | P85: 10 | Q85: 10 | R85: IN | S85: Cubic Feet | T85: Yes | U85: No | V85: Yes | W85: 5 | X85: No | Y85: NA | Z85: 000260018 | AA85: GeneralCargoTemplate | AB85: CreditCard | AC85: NA | AD85: Test1 | AE85: Test2 | AF85: Atlanta | AG85: Georgia | AH85: 55055 | AI85: 171276181 | AJ85: International
A86: =_xlfn.CONCAT("createAndConfirmGuidedBooking",SUBSTITUTE(B86," ","_"),"_",SUBSTITUTE(C86," ","_"),"_",SUBSTITUTE(SUBSTITUTE(SUBSTITUTE(SUBSTITUTE(SUBSTITUTE(SUBSTITUTE(SUBSTITUTE(J86," ",""),"-",""),"/",""),"–",""),"+",""),"°",""),",",""),"_",SUBSTITUTE(AJ86," ","_")) -> createAndConfirmGuidedBookingPetsandLive_SPECIALIZED_LIVE_HatchingEggs_International | B86: PetsandLive | C86: SPECIALIZED LIVE | D86: sumit.choudhary@delta.com | E86: Delta2 | F86: TRUE | G86: NA | H86: ATL | I86: MSP | J86: Hatching Eggs | K86: Test Pet and Live | L86: 10 | M86: KG | N86: 1 | O86: 10 | P86: 10 | Q86: 10 | R86: CM | S86: Cubic Feet | T86: No | U86: No | V86: No | W86: 6 | X86: No | Y86: NA | Z86: 000260018 | AA86: GeneralCargoTemplate | AB86: CreditCard | AC86: NA | AD86: Test1 | AE86: Test2 | AF86: Atlanta | AG86: Georgia | AH86: 55055 | AI86: 171276181 | AJ86: International
A87: =_xlfn.CONCAT("createAndConfirmGuidedBooking",SUBSTITUTE(B87," ","_"),"_",SUBSTITUTE(C87," ","_"),"_",SUBSTITUTE(SUBSTITUTE(SUBSTITUTE(SUBSTITUTE(SUBSTITUTE(SUBSTITUTE(SUBSTITUTE(J87," ",""),"-",""),"/",""),"–",""),"+",""),"°",""),",",""),"_",SUBSTITUTE(AJ87," ","_")) -> createAndConfirmGuidedBookingPetsandLive_SPECIALIZED_LIVE_WarmBloodedAnimal_International | B87: PetsandLive | C87: SPECIALIZED LIVE | D87: sumit.choudhary@delta.com | E87: Delta2 | F87: TRUE | G87: NA | H87: ATL | I87: MSP | J87: Warm Blooded Animal | K87: Test Pet and Live | L87: 90 | M87: LB | N87: 1 | O87: 10 | P87: 10 | Q87: 10 | R87: IN | S87: Cubic Feet | T87: Yes | U87: No | V87: Yes | W87: 7 | X87: No | Y87: NA | Z87: 000260018 | AA87: GeneralCargoTemplate | AB87: CreditCard | AC87: NA | AD87: Test1 | AE87: Test2 | AF87: Atlanta | AG87: Georgia | AH87: 55055 | AI87: 171276181 | AJ87: International
... A97: =_xlfn.CONCAT("createAndConfirmGuidedBooking",SUBSTITUTE(B97," ","_"),"_",SUBSTITUTE(C97," ","_"),"_",SUBSTITUTE(SUBSTITUTE(SUBSTITUTE(SUBSTITUTE(SUBSTITUTE(SUBSTITUTE(SUBSTITUTE(J97," ",""),"-",""),"/",""),"–",""),"+",""),"°",""),",",""),"_",SUBSTITUTE(AJ97," ","_")) -> createAndConfirmGuidedBookingPerishables_CRITICAL_HEAVY_Fresh3Seafoodbetween2Cto25C_International | B97: Perishables | C97: CRITICAL HEAVY | D97: sumit.choudhary@delta.com | E97: Delta2 | F97: TRUE | G97: NA | H97: ATL | I97: CDG | J97: Fresh 3 - Seafood between +2°C to 25°C | K97: Test Perishables | L97: 130 | M97: KG | N97: 1 | O97: 10 | P97: 10 | Q97: 10 | R97: IN | S97: Cubic Feet | T97: No | U97: No | V97: No | W97: 6 | X97: No | Y97: NA | Z97: 000260018 | AA97: GeneralCargoTemplate | AB97: CreditCard | AC97: NA | AD97: Test1 | AE97: Test2 | AF97: Atlanta | AG97: Georgia | AH97: 55055 | AI97: 171276181 | AJ97: International
A98: =_xlfn.CONCAT("createAndConfirmGuidedBooking",SUBSTITUTE(B98," ","_"),"_",SUBSTITUTE(C98," ","_"),"_",SUBSTITUTE(SUBSTITUTE(SUBSTITUTE(SUBSTITUTE(SUBSTITUTE(SUBSTITUTE(SUBSTITUTE(J98," ",""),"-",""),"/",""),"–",""),"+",""),"°",""),",",""),"_",SUBSTITUTE(AJ98," ","_")) -> createAndConfirmGuidedBookingPharma_PHARMA_Pharma1ActiveContainer_Domestic | B98: Pharma | C98: PHARMA | D98: sumit.choudhary@delta.com | E98: Delta2 | F98: TRUE | G98: NA | H98: BOS | I98: SFO | J98: Pharma 1 - Active Container | K98: Test Pharma | L98: 11 | M98: KG | N98: 1 | O98: NA | P98: NA | Q98: NA | R98: NA | S98: NA | T98: No | U98: No | V98: No | W98: 3 | X98: No | Y98: Csafe RAP | Z98: 000260018 | AA98: GeneralCargoTemplate | AB98: CreditCard | AC98: NA | AD98: Test1 | AE98: Test2 | AF98: Atlanta | AG98: Georgia | AH98: 55055 | AI98: 000075010 | AJ98: Domestic
...

Sheet ABGeneralCargo
A1: TestCases | B1: ShipmentContains | C1: ShipmentTypeFromTheList | D1: Execution | E1: LoginUsername | F1: LoginPassword | G1: SearchFlightFlag | H1: guidedBookingOption | I1: ShipmentOrigin | J1: ShipmentDestination | K1: TypeOfShipments | L1: ShipmentDescription | M1: ShipmentWeight | N1: ShipmentWeightUnits | O1: ShipmentQuantity | P1: ShipmentLength | Q1: ShipmentWidth | R1: ShipmentHeight | S1: ShipmentUnit | T1: ShipmentVolumeUnit | U1: ShipmentDoPiecesBeRotated | V1: ShipmentDoPiecesContainDangerousGoods | W1: ShipmentBePreScreened | X1: ShipmentCalendarDate | Y1: ShipmentRequireDeltaContainer | Z1: ContainerType | AA1: RecipientInformationAccountNumber | AB1: ShipmentTemplateName | AC1: ShipmentPaymentMethod | AD1: PetAgeAndUnit | AE1: Address1 | AF1: Address2 | AG1: City | AH1: State | AI1: Postal | AJ1: AccountNumber | AK1: AccountType | AL1: AWB | AM1: ShipmentDoPiecesBeRotated | AN1: ShipmentDoPiecesContainDangerousGoods | AO1: ShipmentBePreScreened
A2: createAndConfirmAdvanceBookingGeneral_Cargo_STANDARD_Loose_Domestic | B2: {=_xlfn.XLOOKUP($A2,DataColumnRange,_xlfn.XLOOKUP(B$1,dataRowRange,ActualDataRange))} -> General Cargo | C2: STANDARD | D2: Yes | E2: {=_xlfn.XLOOKUP($A2,DataColumnRange,_xlfn.XLOOKUP(E$1,dataRowRange,ActualDataRange))} -> sumit.choudhary@delta.com | F2: {=_xlfn.XLOOKUP($A2,DataColumnRange,_xlfn.XLOOKUP(F$1,dataRowRange,ActualDataRange))} -> Delta2 | G2: {=_xlfn.XLOOKUP($A2,DataColumnRange,_xlfn.XLOOKUP(G$1,dataRowRange,ActualDataRange))} -> TRUE | H2: {=_xlfn.XLOOKUP($A2,DataColumnRange,_xlfn.XLOOKUP(H$1,dataRowRange,ActualDataRange))} -> NA | I2: {=_xlfn.XLOOKUP($A2,DataColumnRange,_xlfn.XLOOKUP(I$1,dataRowRange,ActualDataRange))} -> ATL | J2: {=_xlfn.XLOOKUP($A2,DataColumnRange,_xlfn.XLOOKUP(J$1,dataRowRange,ActualDataRange))} -> MSP | K2: {=_xlfn.XLOOKUP($A2,DataColumnRange,_xlfn.XLOOKUP(K$1,dataRowRange,ActualDataRange))} -> Loose | L2: {=_xlfn.XLOOKUP($A2,DataColumnRange,_xlfn.XLOOKUP(L$1,dataRowRange,ActualDataRange))} -> Test General Cargo | ... AO2: {=_xlfn.XLOOKUP($A2,DataColumnRange,_xlfn.XLOOKUP(AO$1,dataRowRange,ActualDataRange))} -> No
A3: createAndConfirmAdvanceBookingGeneral_Cargo_DSH_Loose_Domestic | B3: {=_xlfn.XLOOKUP($A3,DataColumnRange,_xlfn.XLOOKUP(B$1,dataRowRange,ActualDataRange))} -> General Cargo | C3: DSH | D3: Yes | E3: {=_xlfn.XLOOKUP($A3,DataColumnRange,_xlfn.XLOOKUP(E$1,dataRowRange,ActualDataRange))} -> sumit.choudhary@delta.com | F3: {=_xlfn.XLOOKUP($A3,DataColumnRange,_xlfn.XLOOKUP(F$1,dataRowRange,ActualDataRange))} -> Delta2 | G3: {=_xlfn.XLOOKUP($A3,DataColumnRange,_xlfn.XLOOKUP(G$1,dataRowRange,ActualDataRange))} -> TRUE | H3: {=_xlfn.XLOOKUP($A3,DataColumnRange,_xlfn.XLOOKUP(H$1,dataRowRange,ActualDataRange))} -> NA | I3: {=_xlfn.XLOOKUP($A3,DataColumnRange,_xlfn.XLOOKUP(I$1,dataRowRange,ActualDataRange))} -> JFK | J3: {=_xlfn.XLOOKUP($A3,DataColumnRange,_xlfn.XLOOKUP(J$1,dataRowRange,ActualDataRange))} -> ATL | K3: {=_xlfn.XLOOKUP($A3,DataColumnRange,_xlfn.XLOOKUP(K$1,dataRowRange,ActualDataRange))} -> Loose | L3: {=_xlfn.XLOOKUP($A3,DataColumnRange,_xlfn.XLOOKUP(L$1,dataRowRange,ActualDataRange))} -> Test General Cargo | ... AO3: {=_xlfn.XLOOKUP($A3,DataColumnRange,_xlfn.XLOOKUP(AO$1,dataRowRange,ActualDataRange))} -> No
A4: createAndConfirmAdvanceBookingGeneral_Cargo_DMD_Loose_Domestic | B4: {=_xlfn.XLOOKUP($A4,DataColumnRange,_xlfn.XLOOKUP(B$1,dataRowRange,ActualDataRange))} -> General Cargo | C4: DMD | D4: =IF(TestCaseConfig!$B$2="Yes","Yes","No") -> Yes | E4: {=_xlfn.XLOOKUP($A4,DataColumnRange,_xlfn.XLOOKUP(E$1,dataRowRange,ActualDataRange))} -> sumit.choudhary@delta.com | F4: {=_xlfn.XLOOKUP($A4,DataColumnRange,_xlfn.XLOOKUP(F$1,dataRowRange,ActualDataRange))} -> Delta2 | G4: {=_xlfn.XLOOKUP($A4,DataColumnRange,_xlfn.XLOOKUP(G$1,dataRowRange,ActualDataRange))} -> TRUE | H4: {=_xlfn.XLOOKUP($A4,DataColumnRange,_xlfn.XLOOKUP(H$1,dataRowRange,ActualDataRange))} -> NA | I4: {=_xlfn.XLOOKUP($A4,DataColumnRange,_xlfn.XLOOKUP(I$1,dataRowRange,ActualDataRange))} -> JFK | J4: {=_xlfn.XLOOKUP($A4,DataColumnRange,_xlfn.XLOOKUP(J$1,dataRowRange,ActualDataRange))} -> DTW | K4: {=_xlfn.XLOOKUP($A4,DataColumnRange,_xlfn.XLOOKUP(K$1,dataRowRange,ActualDataRange))} -> Loose | L4: {=_xlfn.XLOOKUP($A4,DataColumnRange,_xlfn.XLOOKUP(L$1,dataRowRange,ActualDataRange))} -> Test General Cargo | ... AO4: {=_xlfn.XLOOKUP($A4,DataColumnRange,_xlfn.XLOOKUP(AO$1,dataRowRange,ActualDataRange))} -> No
A5: createAndConfirmAdvanceBookingGeneral_Cargo_STANDARD_Loose_International | B5: {=_xlfn.XLOOKUP($A5,DataColumnRange,_xlfn.XLOOKUP(B$1,dataRowRange,ActualDataRange))} -> General Cargo | C5: General | D5: =IF(TestCaseConfig!$B$2="Yes","Yes","No") -> Yes | E5: {=_xlfn.XLOOKUP($A5,DataColumnRange,_xlfn.XLOOKUP(E$1,dataRowRange,ActualDataRange))} -> sumit.choudhary@delta.com | F5: {=_xlfn.XLOOKUP($A5,DataColumnRange,_xlfn.XLOOKUP(F$1,dataRowRange,ActualDataRange))} -> Delta2 | G5: {=_xlfn.XLOOKUP($A5,DataColumnRange,_xlfn.XLOOKUP(G$1,dataRowRange,ActualDataRange))} -> TRUE | H5: {=_xlfn.XLOOKUP($A5,DataColumnRange,_xlfn.XLOOKUP(H$1,dataRowRange,ActualDataRange))} -> NA | I5: {=_xlfn.XLOOKUP($A5,DataColumnRange,_xlfn.XLOOKUP(I$1,dataRowRange,ActualDataRange))} -> ATL | J5: {=_xlfn.XLOOKUP($A5,DataColumnRange,_xlfn.XLOOKUP(J$1,dataRowRange,ActualDataRange))} -> MSP | K5: {=_xlfn.XLOOKUP($A5,DataColumnRange,_xlfn.XLOOKUP(K$1,dataRowRange,ActualDataRange))} -> Loose | L5: {=_xlfn.XLOOKUP($A5,DataColumnRange,_xlfn.XLOOKUP(L$1,dataRowRange,ActualDataRange))} -> Test General Cargo | ... AO5: {=_xlfn.XLOOKUP($A5,DataColumnRange,_xlfn.XLOOKUP(AO$1,dataRowRange,ActualDataRange))} -> No
A6: createAndConfirmAdvanceBookingGeneral_Cargo_DSH_Loose_International | B6: {=_xlfn.XLOOKUP($A6,DataColumnRange,_xlfn.XLOOKUP(B$1,dataRowRange,ActualDataRange))} -> General Cargo | C6: Express | D6: =IF(TestCaseConfig!$B$2="Yes","Yes","No") -> Yes | E6: {=_xlfn.XLOOKUP($A6,DataColumnRange,_xlfn.XLOOKUP(E$1,dataRowRange,ActualDataRange))} -> sumit.choudhary@delta.com | F6: {=_xlfn.XLOOKUP($A6,DataColumnRange,_xlfn.XLOOKUP(F$1,dataRowRange,ActualDataRange))} -> Delta2 | G6: {=_xlfn.XLOOKUP($A6,DataColumnRange,_xlfn.XLOOKUP(G$1,dataRowRange,ActualDataRange))} -> TRUE | H6: {=_xlfn.XLOOKUP($A6,DataColumnRange,_xlfn.XLOOKUP(H$1,dataRowRange,ActualDataRange))} -> NA | I6: {=_xlfn.XLOOKUP($A6,DataColumnRange,_xlfn.XLOOKUP(I$1,dataRowRange,ActualDataRange))} -> JFK | J6: {=_xlfn.XLOOKUP($A6,DataColumnRange,_xlfn.XLOOKUP(J$1,dataRowRange,ActualDataRange))} -> ATL | K6: {=_xlfn.XLOOKUP($A6,DataColumnRange,_xlfn.XLOOKUP(K$1,dataRowRange,ActualDataRange))} -> Loose | L6: {=_xlfn.XLOOKUP($A6,DataColumnRange,_xlfn.XLOOKUP(L$1,dataRowRange,ActualDataRange))} -> Test General Cargo | ... AO6: {=_xlfn.XLOOKUP($A6,DataColumnRange,_xlfn.XLOOKUP(AO$1,dataRowRange,ActualDataRange))} -> No
A7: createAndConfirmAdvanceBookingGeneral_Cargo_DMD_Loose_International | B7: {=_xlfn.XLOOKUP($A7,DataColumnRange,_xlfn.XLOOKUP(B$1,dataRowRange,ActualDataRange))} -> General Cargo | C7: Express Heavy | D7: =IF(TestCaseConfig!$B$2="Yes","Yes","No") -> Yes | E7: {=_xlfn.XLOOKUP($A7,DataColumnRange,_xlfn.XLOOKUP(E$1,dataRowRange,ActualDataRange))} -> sumit.choudhary@delta.com | F7: {=_xlfn.XLOOKUP($A7,DataColumnRange,_xlfn.XLOOKUP(F$1,dataRowRange,ActualDataRange))} -> Delta2 | G7: {=_xlfn.XLOOKUP($A7,DataColumnRange,_xlfn.XLOOKUP(G$1,dataRowRange,ActualDataRange))} -> TRUE | H7: {=_xlfn.XLOOKUP($A7,DataColumnRange,_xlfn.XLOOKUP(H$1,dataRowRange,ActualDataRange))} -> NA | I7: {=_xlfn.XLOOKUP($A7,DataColumnRange,_xlfn.XLOOKUP(I$1,dataRowRange,ActualDataRange))} -> JFK | J7: {=_xlfn.XLOOKUP($A7,DataColumnRange,_xlfn.XLOOKUP(J$1,dataRowRange,ActualDataRange))} -> DTW | K7: {=_xlfn.XLOOKUP($A7,DataColumnRange,_xlfn.XLOOKUP(K$1,dataRowRange,ActualDataRange))} -> Loose | L7: {=_xlfn.XLOOKUP($A7,DataColumnRange,_xlfn.XLOOKUP(L$1,dataRowRange,ActualDataRange))} -> Test General Cargo | ... AO7: {=_xlfn.XLOOKUP($A7,DataColumnRange,_xlfn.XLOOKUP(AO$1,dataRowRange,ActualDataRange))} -> No

Sheet ABPerishable
A1: TestCases | B1: ShipmentContains | C1: ShipmentTypeFromTheList | D1: Execution | E1: LoginUsername | F1: LoginPassword | G1: SearchFlightFlag | H1: guidedBookingOption | I1: ShipmentOrigin | J1: ShipmentDestination | K1: TypeOfShipments | L1: ShipmentDescription | M1: ShipmentWeight | N1: ShipmentWeightUnits | O1: ShipmentQuantity | P1: ShipmentLength | Q1: ShipmentWidth | R1: ShipmentHeight | S1: ShipmentUnit | T1: ShipmentVolumeUnit | U1: ShipmentDoPiecesBeRotated | V1: ShipmentDoPiecesContainDangerousGoods | W1: ShipmentBePreScreened | X1: ShipmentCalendarDate | Y1: ShipmentRequireDeltaContainer | Z1: ContainerType | AA1: RecipientInformationAccountNumber | AB1: ShipmentTemplateName | AC1: ShipmentPaymentMethod | AD1: PetAgeAndUnit | AE1: Address1 | AF1: Address2 | AG1: City | AH1: State | AI1: Postal | AJ1: AccountNumber | AK1: AccountType | AL1: AWB
A2: createAndConfirmAdvanceBookingPerishable_FRESH_Fresh1Activecontainer_Domestic | B2: Perishable | C2: FRESH | D2: =IF(TestCaseConfig!$B$3="Yes","Yes","No") -> Yes | E2: {=_xlfn.XLOOKUP($A2,DataColumnRange,_xlfn.XLOOKUP(E$1,dataRowRange,ActualDataRange))} -> sumit.choudhary@delta.com | F2: {=_xlfn.XLOOKUP($A2,DataColumnRange,_xlfn.XLOOKUP(F$1,dataRowRange,ActualDataRange))} -> Delta2 | G2: {=_xlfn.XLOOKUP($A2,DataColumnRange,_xlfn.XLOOKUP(G$1,dataRowRange,ActualDataRange))} -> TRUE | H2: {=_xlfn.XLOOKUP($A2,DataColumnRange,_xlfn.XLOOKUP(H$1,dataRowRange,ActualDataRange))} -> NA | I2: {=_xlfn.XLOOKUP($A2,DataColumnRange,_xlfn.XLOOKUP(I$1,dataRowRange,ActualDataRange))} -> ATL | J2: {=_xlfn.XLOOKUP($A2,DataColumnRange,_xlfn.XLOOKUP(J$1,dataRowRange,ActualDataRange))} -> MSP | K2: {=_xlfn.XLOOKUP($A2,DataColumnRange,_xlfn.XLOOKUP(K$1,dataRowRange,ActualDataRange))} -> Fresh 1 - Active container | L2: {=_xlfn.XLOOKUP($A2,DataColumnRange,_xlfn.XLOOKUP(L$1,dataRowRange,ActualDataRange))} -> Test Perishables | ... AL2: {=_xlfn.XLOOKUP($A2,DataColumnRange,_xlfn.XLOOKUP(AL$1,dataRowRange,ActualDataRange))} -> 0
A3: createAndConfirmAdvanceBookingPerishable_FRESH_Fresh2Temperaturecontrolledbetween2Cto8C_Domestic | B3: Perishable | C3: FRESH | D3: =IF(TestCaseConfig!$B$3="Yes","Yes","No") -> Yes | E3: {=_xlfn.XLOOKUP($A3,DataColumnRange,_xlfn.XLOOKUP(E$1,dataRowRange,ActualDataRange))} -> sumit.choudhary@delta.com | F3: {=_xlfn.XLOOKUP($A3,DataColumnRange,_xlfn.XLOOKUP(F$1,dataRowRange,ActualDataRange))} -> Delta2 | G3: {=_xlfn.XLOOKUP($A3,DataColumnRange,_xlfn.XLOOKUP(G$1,dataRowRange,ActualDataRange))} -> TRUE | H3: {=_xlfn.XLOOKUP($A3,DataColumnRange,_xlfn.XLOOKUP(H$1,dataRowRange,ActualDataRange))} -> NA | I3: {=_xlfn.XLOOKUP($A3,DataColumnRange,_xlfn.XLOOKUP(I$1,dataRowRange,ActualDataRange))} -> JFK | J3: {=_xlfn.XLOOKUP($A3,DataColumnRange,_xlfn.XLOOKUP(J$1,dataRowRange,ActualDataRange))} -> ATL | K3: {=_xlfn.XLOOKUP($A3,DataColumnRange,_xlfn.XLOOKUP(K$1,dataRowRange,ActualDataRange))} -> Fresh 2 - Temperature controlled between +2°C to 8°C | L3: {=_xlfn.XLOOKUP($A3,DataColumnRange,_xlfn.XLOOKUP(L$1,dataRowRange,ActualDataRange))} -> Test Perishables | ... AL3: {=_xlfn.XLOOKUP($A3,DataColumnRange,_xlfn.XLOOKUP(AL$1,dataRowRange,ActualDataRange))} -> 0
A4: createAndConfirmAdvanceBookingPerishable_DASH_Fresh3Flowersbetween2Cto25C_Domestic | B4: Perishable | C4: DASH | D4: =IF(TestCaseConfig!$B$3="Yes","Yes","No") -> Yes | E4: {=_xlfn.XLOOKUP($A4,DataColumnRange,_xlfn.XLOOKUP(E$1,dataRowRange,ActualDataRange))} -> sumit.choudhary@delta.com | F4: {=_xlfn.XLOOKUP($A4,DataColumnRange,_xlfn.XLOOKUP(F$1,dataRowRange,ActualDataRange))} -> Delta2 | G4: {=_xlfn.XLOOKUP($A4,DataColumnRange,_xlfn.XLOOKUP(G$1,dataRowRange,ActualDataRange))} -> TRUE | H4: {=_xlfn.XLOOKUP($A4,DataColumnRange,_xlfn.XLOOKUP(H$1,dataRowRange,ActualDataRange))} -> NA | I4: {=_xlfn.XLOOKUP($A4,DataColumnRange,_xlfn.XLOOKUP(I$1,dataRowRange,ActualDataRange))} -> JFK | J4: {=_xlfn.XLOOKUP($A4,DataColumnRange,_xlfn.XLOOKUP(J$1,dataRowRange,ActualDataRange))} -> DTW | K4: {=_xlfn.XLOOKUP($A4,DataColumnRange,_xlfn.XLOOKUP(K$1,dataRowRange,ActualDataRange))} -> Fresh 3 - Flowers between +2°C to 25°C | L4: {=_xlfn.XLOOKUP($A4,DataColumnRange,_xlfn.XLOOKUP(L$1,dataRowRange,ActualDataRange))} -> Test Perishables | ... AL4: {=_xlfn.XLOOKUP($A4,DataColumnRange,_xlfn.XLOOKUP(AL$1,dataRowRange,ActualDataRange))} -> 0
A5: createAndConfirmAdvanceBookingPerishable_DHV_Fresh3Foodstuffsbetween2Cto25C_Domestic | B5: Perishable | C5: DHV | D5: =IF(TestCaseConfig!$B$3="Yes","Yes","No") -> Yes | E5: {=_xlfn.XLOOKUP($A5,DataColumnRange,_xlfn.XLOOKUP(E$1,dataRowRange,ActualDataRange))} -> sumit.choudhary@delta.com | F5: {=_xlfn.XLOOKUP($A5,DataColumnRange,_xlfn.XLOOKUP(F$1,dataRowRange,ActualDataRange))} -> Delta2 | G5: {=_xlfn.XLOOKUP($A5,DataColumnRange,_xlfn.XLOOKUP(G$1,dataRowRange,ActualDataRange))} -> TRUE | H5: {=_xlfn.XLOOKUP($A5,DataColumnRange,_xlfn.XLOOKUP(H$1,dataRowRange,ActualDataRange))} -> NA | I5: {=_xlfn.XLOOKUP($A5,DataColumnRange,_xlfn.XLOOKUP(I$1,dataRowRange,ActualDataRange))} -> ATL | J5: {=_xlfn.XLOOKUP($A5,DataColumnRange,_xlfn.XLOOKUP(J$1,dataRowRange,ActualDataRange))} -> MSP | K5: {=_xlfn.XLOOKUP($A5,DataColumnRange,_xlfn.XLOOKUP(K$1,dataRowRange,ActualDataRange))} -> Fresh 3 - Foodstuffs between +2°C to 25°C | L5: {=_xlfn.XLOOKUP($A5,DataColumnRange,_xlfn.XLOOKUP(L$1,dataRowRange,ActualDataRange))} -> Test Perishables | ... AL5: {=_xlfn.XLOOKUP($A5,DataColumnRange,_xlfn.XLOOKUP(AL$1,dataRowRange,ActualDataRange))} -> 0
A6: createAndConfirmAdvanceBookingPerishable_DMD_Fresh3Seafoodbetween2Cto25C_Domestic | B6: Perishable | C6: DMD | D6: =IF(TestCaseConfig!$B$3="Yes","Yes","No") -> Yes | E6: {=_xlfn.XLOOKUP($A6,DataColumnRange,_xlfn.XLOOKUP(E$1,dataRowRange,ActualDataRange))} -> sumit.choudhary@delta.com | F6: {=_xlfn.XLOOKUP($A6,DataColumnRange,_xlfn.XLOOKUP(F$1,dataRowRange,ActualDataRange))} -> Delta2 | G6: {=_xlfn.XLOOKUP($A6,DataColumnRange,_xlfn.XLOOKUP(G$1,dataRowRange,ActualDataRange))} -> TRUE | H6: {=_xlfn.XLOOKUP($A6,DataColumnRange,_xlfn.XLOOKUP(H$1,dataRowRange,ActualDataRange))} -> NA | I6: {=_xlfn.XLOOKUP($A6,DataColumnRange,_xlfn.XLOOKUP(I$1,dataRowRange,ActualDataRange))} -> JFK | J6: {=_xlfn.XLOOKUP($A6,DataColumnRange,_xlfn.XLOOKUP(J$1,dataRowRange,ActualDataRange))} -> ATL | K6: {=_xlfn.XLOOKUP($A6,DataColumnRange,_xlfn.XLOOKUP(K$1,dataRowRange,ActualDataRange))} -> Fresh 3 - Seafood between +2°C to 25°C | L6: {=_xlfn.XLOOKUP($A6,DataColumnRange,_xlfn.XLOOKUP(L$1,dataRowRange,ActualDataRange))} -> Test Perishables | ... AL6: {=_xlfn.XLOOKUP($A6,DataColumnRange,_xlfn.XLOOKUP(AL$1,dataRowRange,ActualDataRange))} -> 0
A7: createAndConfirmAdvanceBookingPerishable_FRESH_Fresh1Activecontainer_International | B7: Perishable | C7: FRESH | D7: =IF(TestCaseConfig!$B$3="Yes","Yes","No") -> Yes | E7: {=_xlfn.XLOOKUP($A7,DataColumnRange,_xlfn.XLOOKUP(E$1,dataRowRange,ActualDataRange))} -> sumit.choudhary@delta.com | F7: {=_xlfn.XLOOKUP($A7,DataColumnRange,_xlfn.XLOOKUP(F$1,dataRowRange,ActualDataRange))} -> Delta2 | G7: {=_xlfn.XLOOKUP($A7,DataColumnRange,_xlfn.XLOOKUP(G$1,dataRowRange,ActualDataRange))} -> TRUE | H7: {=_xlfn.XLOOKUP($A7,DataColumnRange,_xlfn.XLOOKUP(H$1,dataRowRange,ActualDataRange))} -> NA | I7: {=_xlfn.XLOOKUP($A7,DataColumnRange,_xlfn.XLOOKUP(I$1,dataRowRange,ActualDataRange))} -> ATL | J7: {=_xlfn.XLOOKUP($A7,DataColumnRange,_xlfn.XLOOKUP(J$1,dataRowRange,ActualDataRange))} -> MSP | K7: {=_xlfn.XLOOKUP($A7,DataColumnRange,_xlfn.XLOOKUP(K$1,dataRowRange,ActualDataRange))} -> Fresh 1 - Active container | L7: {=_xlfn.XLOOKUP($A7,DataColumnRange,_xlfn.XLOOKUP(L$1,dataRowRange,ActualDataRange))} -> Test Perishables | ... AL7: {=_xlfn.XLOOKUP($A7,DataColumnRange,_xlfn.XLOOKUP(AL$1,dataRowRange,ActualDataRange))} -> 0
A8: createAndConfirmAdvanceBookingPerishable_FRESH_Fresh2Temperaturecontrolledbetween2Cto8C_International | B8: Perishable | C8: FRESH | D8: =IF(TestCaseConfig!$B$3="Yes","Yes","No") -> Yes | E8: {=_xlfn.XLOOKUP($A8,DataColumnRange,_xlfn.XLOOKUP(E$1,dataRowRange,ActualDataRange))} -> sumit.choudhary@delta.com | F8: {=_xlfn.XLOOKUP($A8,DataColumnRange,_xlfn.XLOOKUP(F$1,dataRowRange,ActualDataRange))} -> Delta2 | G8: {=_xlfn.XLOOKUP($A8,DataColumnRange,_xlfn.XLOOKUP(G$1,dataRowRange,ActualDataRange))} -> TRUE | H8: {=_xlfn.XLOOKUP($A8,DataColumnRange,_xlfn.XLOOKUP(H$1,dataRowRange,ActualDataRange))} -> NA | I8: {=_xlfn.XLOOKUP($A8,DataColumnRange,_xlfn.XLOOKUP(I$1,dataRowRange,ActualDataRange))} -> JFK | J8: {=_xlfn.XLOOKUP($A8,DataColumnRange,_xlfn.XLOOKUP(J$1,dataRowRange,ActualDataRange))} -> ATL | K8: {=_xlfn.XLOOKUP($A8,DataColumnRange,_xlfn.XLOOKUP(K$1,dataRowRange,ActualDataRange))} -> Fresh 2 - Temperature controlled between +2°C to 8°C | L8: {=_xlfn.XLOOKUP($A8,DataColumnRange,_xlfn.XLOOKUP(L$1,dataRowRange,ActualDataRange))} -> Test Perishables | ... AL8: {=_xlfn.XLOOKUP($A8,DataColumnRange,_xlfn.XLOOKUP(AL$1,dataRowRange,ActualDataRange))} -> 0
A9: createAndConfirmAdvanceBookingPerishable_DASH_Fresh3Flowersbetween2Cto25C_International | B9: Perishable | C9: DASH | D9: =IF(TestCaseConfig!$B$3="Yes","Yes","No") -> Yes | E9: {=_xlfn.XLOOKUP($A9,DataColumnRange,_xlfn.XLOOKUP(E$1,dataRowRange,ActualDataRange))} -> sumit.choudhary@delta.com | F9: {=_xlfn.XLOOKUP($A9,DataColumnRange,_xlfn.XLOOKUP(F$1,dataRowRange,ActualDataRange))} -> Delta2 | G9: {=_xlfn.XLOOKUP($A9,DataColumnRange,_xlfn.XLOOKUP(G$1,dataRowRange,ActualDataRange))} -> TRUE | H9: {=_xlfn.XLOOKUP($A9,DataColumnRange,_xlfn.XLOOKUP(H$1,dataRowRange,ActualDataRange))} -> NA | I9: {=_xlfn.XLOOKUP($A9,DataColumnRange,_xlfn.XLOOKUP(I$1,dataRowRange,ActualDataRange))} -> JFK | J9: {=_xlfn.XLOOKUP($A9,DataColumnRange,_xlfn.XLOOKUP(J$1,dataRowRange,ActualDataRange))} -> DTW | K9: {=_xlfn.XLOOKUP($A9,DataColumnRange,_xlfn.XLOOKUP(K$1,dataRowRange,ActualDataRange))} -> Fresh 3 - Flowers between +2°C to 25°C | L9: {=_xlfn.XLOOKUP($A9,DataColumnRange,_xlfn.XLOOKUP(L$1,dataRowRange,ActualDataRange))} -> Test Perishables | ... AL9: {=_xlfn.XLOOKUP($A9,DataColumnRange,_xlfn.XLOOKUP(AL$1,dataRowRange,ActualDataRange))} -> 0
A10: createAndConfirmAdvanceBookingPerishable_DHV_Fresh3Foodstuffsbetween2Cto25C_International | B10: Perishable | C10: DHV | D10: =IF(TestCaseConfig!$B$3="Yes","Yes","No") -> Yes | E10: {=_xlfn.XLOOKUP($A10,DataColumnRange,_xlfn.XLOOKUP(E$1,dataRowRange,ActualDataRange))} -> sumit.choudhary@delta.com | F10: {=_xlfn.XLOOKUP($A10,DataColumnRange,_xlfn.XLOOKUP(F$1,dataRowRange,ActualDataRange))} -> Delta2 | G10: {=_xlfn.XLOOKUP($A10,DataColumnRange,_xlfn.XLOOKUP(G$1,dataRowRange,ActualDataRange))} -> TRUE | H10: {=_xlfn.XLOOKUP($A10,DataColumnRange,_xlfn.XLOOKUP(H$1,dataRowRange,ActualDataRange))} -> NA | I10: {=_xlfn.XLOOKUP($A10,DataColumnRange,_xlfn.XLOOKUP(I$1,dataRowRange,ActualDataRange))} -> ATL | J10: {=_xlfn.XLOOKUP($A10,DataColumnRange,_xlfn.XLOOKUP(J$1,dataRowRange,ActualDataRange))} -> MSP | K10: {=_xlfn.XLOOKUP($A10,DataColumnRange,_xlfn.XLOOKUP(K$1,dataRowRange,ActualDataRange))} -> Fresh 3 - Foodstuffs between +2°C to 25°C | L10: {=_xlfn.XLOOKUP($A10,DataColumnRange,_xlfn.XLOOKUP(L$1,dataRowRange,ActualDataRange))} -> Test Perishables | ... AL10: {=_xlfn.XLOOKUP($A10,DataColumnRange,_xlfn.XLOOKUP(AL$1,dataRowRange,ActualDataRange))} -> 0
A11: createAndConfirmAdvanceBookingPerishable_DMD_Fresh3Seafoodbetween2Cto25C_International | B11: Perishable | C11: DMD | D11: =IF(TestCaseConfig!$B$3="Yes","Yes","No") -> Yes | E11: {=_xlfn.XLOOKUP($A11,DataColumnRange,_xlfn.XLOOKUP(E$1,dataRowRange,ActualDataRange))} -> sumit.choudhary@delta.com | F11: {=_xlfn.XLOOKUP($A11,DataColumnRange,_xlfn.XLOOKUP(F$1,dataRowRange,ActualDataRange))} -> Delta2 | G11: {=_xlfn.XLOOKUP($A11,DataColumnRange,_xlfn.XLOOKUP(G$1,dataRowRange,ActualDataRange))} -> TRUE | H11: {=_xlfn.XLOOKUP($A11,DataColumnRange,_xlfn.XLOOKUP(H$1,dataRowRange,ActualDataRange))} -> NA | I11: {=_xlfn.XLOOKUP($A11,DataColumnRange,_xlfn.XLOOKUP(I$1,dataRowRange,ActualDataRange))} -> JFK | J11: {=_xlfn.XLOOKUP($A11,DataColumnRange,_xlfn.XLOOKUP(J$1,dataRowRange,ActualDataRange))} -> ATL | K11: {=_xlfn.XLOOKUP($A11,DataColumnRange,_xlfn.XLOOKUP(K$1,dataRowRange,ActualDataRange))} -> Fresh 3 - Seafood between +2°C to 25°C | L11: {=_xlfn.XLOOKUP($A11,DataColumnRange,_xlfn.XLOOKUP(L$1,dataRowRange,ActualDataRange))} -> Test Perishables | ... AL11: {=_xlfn.XLOOKUP($A11,DataColumnRange,_xlfn.XLOOKUP(AL$1,dataRowRange,ActualDataRange))} -> 0

Sheet ABPharma
A1: Testcase | B1: ShipmentContains | C1: ShipmentTypeFromTheList | D1: Execution | E1: LoginUsername | F1: LoginPassword | G1: SearchFlightFlag | H1: guidedBookingOption | I1: ShipmentOrigin | J1: ShipmentDestination | K1: TypeOfShipments | L1: ShipmentDescription | M1: ShipmentWeight | N1: ShipmentWeightUnits | O1: ShipmentQuantity | P1: ShipmentLength | Q1: ShipmentWidth | R1: ShipmentHeight | S1: ShipmentUnit | T1: ShipmentVolumeUnit | U1: ShipmentDoPiecesBeRotated | V1: ShipmentDoPiecesContainDangerousGoods | W1: ShipmentBePreScreened | X1: ShipmentCalendarDate | Y1: ShipmentRequireDeltaContainer | Z1: ContainerType | AA1: RecipientInformationAccountNumber | AB1: ShipmentTemplateName | AC1: ShipmentPaymentMethod | AD1: PetAgeAndUnit | AE1: Address1 | AF1: Address2 | AG1: City | AH1: State | AI1: Postal | AJ1: AccountNumber | AK1: AccountType | AL1: AWB
A2: createAndConfirmAdvanceBookingPharmaceuticals_PHARMA_Pharma1ActiveContainer_Domestic | B2: Pharmaceuticals | C2: PHARMA | D2: =IF(TestCaseConfig!$B$3="Yes","Yes","No") -> Yes | E2: {=_xlfn.XLOOKUP($A2,DataColumnRange,_xlfn.XLOOKUP(E$1,dataRowRange,ActualDataRange))} -> sumit.choudhary@delta.com | F2: {=_xlfn.XLOOKUP($A2,DataColumnRange,_xlfn.XLOOKUP(F$1,dataRowRange,ActualDataRange))} -> Delta2 | G2: {=_xlfn.XLOOKUP($A2,DataColumnRange,_xlfn.XLOOKUP(G$1,dataRowRange,ActualDataRange))} -> TRUE | H2: {=_xlfn.XLOOKUP($A2,DataColumnRange,_xlfn.XLOOKUP(H$1,dataRowRange,ActualDataRange))} -> NA | I2: {=_xlfn.XLOOKUP($A2,DataColumnRange,_xlfn.XLOOKUP(I$1,dataRowRange,ActualDataRange))} -> JFK | J2: {=_xlfn.XLOOKUP($A2,DataColumnRange,_xlfn.XLOOKUP(J$1,dataRowRange,ActualDataRange))} -> ATL | K2: {=_xlfn.XLOOKUP($A2,DataColumnRange,_xlfn.XLOOKUP(K$1,dataRowRange,ActualDataRange))} -> Pharma 1 - Active Container | L2: {=_xlfn.XLOOKUP($A2,DataColumnRange,_xlfn.XLOOKUP(L$1,dataRowRange,ActualDataRange))} -> Test Pharma | ... AL2: {=_xlfn.XLOOKUP($A2,DataColumnRange,_xlfn.XLOOKUP(AL$1,dataRowRange,ActualDataRange))} -> 0
A3: createAndConfirmAdvanceBookingPharmaceuticals_PHARMA_Pharma1PassiveContainer_Domestic | B3: Pharmaceuticals | C3: PHARMA | D3: =IF(TestCaseConfig!$B$3="Yes","Yes","No") -> Yes | E3: {=_xlfn.XLOOKUP($A3,DataColumnRange,_xlfn.XLOOKUP(E$1,dataRowRange,ActualDataRange))} -> sumit.choudhary@delta.com | F3: {=_xlfn.XLOOKUP($A3,DataColumnRange,_xlfn.XLOOKUP(F$1,dataRowRange,ActualDataRange))} -> Delta2 | G3: {=_xlfn.XLOOKUP($A3,DataColumnRange,_xlfn.XLOOKUP(G$1,dataRowRange,ActualDataRange))} -> TRUE | H3: {=_xlfn.XLOOKUP($A3,DataColumnRange,_xlfn.XLOOKUP(H$1,dataRowRange,ActualDataRange))} -> NA | I3: {=_xlfn.XLOOKUP($A3,DataColumnRange,_xlfn.XLOOKUP(I$1,dataRowRange,ActualDataRange))} -> JFK | J3: {=_xlfn.XLOOKUP($A3,DataColumnRange,_xlfn.XLOOKUP(J$1,dataRowRange,ActualDataRange))} -> ATL | K3: {=_xlfn.XLOOKUP($A3,DataColumnRange,_xlfn.XLOOKUP(K$1,dataRowRange,ActualDataRange))} -> Pharma 1 - Passive Container | L3: {=_xlfn.XLOOKUP($A3,DataColumnRange,_xlfn.XLOOKUP(L$1,dataRowRange,ActualDataRange))} -> Test Pharma | ... AL3: {=_xlfn.XLOOKUP($A3,DataColumnRange,_xlfn.XLOOKUP(AL$1,dataRowRange,ActualDataRange))} -> 0
